2021-04-16 22:13:57,661 There is custom code (custom.py) associated with this                           project but it doesn't import cleanly.  Raising exception,
[2021-04-16 22:13:57 -0400] [116682] [ERROR] Exception in worker process
Traceback (most recent call last):
  File "/home/nachshon/anaconda3/envs/psiturk/lib/python3.8/site-packages/gunicorn/arbiter.py", line 583, in spawn_worker
    worker.init_process()
  File "/home/nachshon/anaconda3/envs/psiturk/lib/python3.8/site-packages/gunicorn/workers/base.py", line 129, in init_process
    self.load_wsgi()
  File "/home/nachshon/anaconda3/envs/psiturk/lib/python3.8/site-packages/gunicorn/workers/base.py", line 138, in load_wsgi
    self.wsgi = self.app.wsgi()
  File "/home/nachshon/anaconda3/envs/psiturk/lib/python3.8/site-packages/gunicorn/app/base.py", line 67, in wsgi
    self.callable = self.load()
  File "/home/nachshon/anaconda3/envs/psiturk/lib/python3.8/site-packages/psiturk/experiment_server.py", line 48, in load
    return util.import_app("psiturk.experiment:app")
  File "/home/nachshon/anaconda3/envs/psiturk/lib/python3.8/site-packages/gunicorn/util.py", line 350, in import_app
    __import__(module)
  File "/home/nachshon/anaconda3/envs/psiturk/lib/python3.8/site-packages/psiturk/experiment.py", line 77, in <module>
    from custom import custom_code
  File "/home/nachshon/Documents/Projects/WMDM/webversion/heroku/nachshon-wmdm/custom.py", line 8, in <module>
    from psiturk.experiment_errors import ExperimentError, InvalidUsageError
ImportError: cannot import name 'InvalidUsageError' from 'psiturk.experiment_errors' (/home/nachshon/anaconda3/envs/psiturk/lib/python3.8/site-packages/psiturk/experiment_errors.py)
2021-04-16 22:28:38,403 There is custom code (custom.py) associated with this                           project but it doesn't import cleanly.  Raising exception,
[2021-04-16 22:28:38 -0400] [117076] [ERROR] Exception in worker process
Traceback (most recent call last):
  File "/home/nachshon/anaconda3/envs/psiturk/lib/python3.8/site-packages/gunicorn/arbiter.py", line 583, in spawn_worker
    worker.init_process()
  File "/home/nachshon/anaconda3/envs/psiturk/lib/python3.8/site-packages/gunicorn/workers/base.py", line 129, in init_process
    self.load_wsgi()
  File "/home/nachshon/anaconda3/envs/psiturk/lib/python3.8/site-packages/gunicorn/workers/base.py", line 138, in load_wsgi
    self.wsgi = self.app.wsgi()
  File "/home/nachshon/anaconda3/envs/psiturk/lib/python3.8/site-packages/gunicorn/app/base.py", line 67, in wsgi
    self.callable = self.load()
  File "/home/nachshon/anaconda3/envs/psiturk/lib/python3.8/site-packages/psiturk/experiment_server.py", line 48, in load
    return util.import_app("psiturk.experiment:app")
  File "/home/nachshon/anaconda3/envs/psiturk/lib/python3.8/site-packages/gunicorn/util.py", line 350, in import_app
    __import__(module)
  File "/home/nachshon/anaconda3/envs/psiturk/lib/python3.8/site-packages/psiturk/experiment.py", line 77, in <module>
    from custom import custom_code
  File "/home/nachshon/Documents/Projects/WMDM/webversion/heroku/nachshon-wmdm/custom.py", line 8, in <module>
    from psiturk.experiment_errors import ExperimentError, InvalidUsageError
ImportError: cannot import name 'InvalidUsageError' from 'psiturk.experiment_errors' (/home/nachshon/anaconda3/envs/psiturk/lib/python3.8/site-packages/psiturk/experiment_errors.py)
2021-04-16 22:29:05,191 There is custom code (custom.py) associated with this                           project but it doesn't import cleanly.  Raising exception,
[2021-04-16 22:29:05 -0400] [117101] [ERROR] Exception in worker process
Traceback (most recent call last):
  File "/home/nachshon/anaconda3/envs/psiturk/lib/python3.8/site-packages/gunicorn/arbiter.py", line 583, in spawn_worker
    worker.init_process()
  File "/home/nachshon/anaconda3/envs/psiturk/lib/python3.8/site-packages/gunicorn/workers/base.py", line 129, in init_process
    self.load_wsgi()
  File "/home/nachshon/anaconda3/envs/psiturk/lib/python3.8/site-packages/gunicorn/workers/base.py", line 138, in load_wsgi
    self.wsgi = self.app.wsgi()
  File "/home/nachshon/anaconda3/envs/psiturk/lib/python3.8/site-packages/gunicorn/app/base.py", line 67, in wsgi
    self.callable = self.load()
  File "/home/nachshon/anaconda3/envs/psiturk/lib/python3.8/site-packages/psiturk/experiment_server.py", line 48, in load
    return util.import_app("psiturk.experiment:app")
  File "/home/nachshon/anaconda3/envs/psiturk/lib/python3.8/site-packages/gunicorn/util.py", line 350, in import_app
    __import__(module)
  File "/home/nachshon/anaconda3/envs/psiturk/lib/python3.8/site-packages/psiturk/experiment.py", line 77, in <module>
    from custom import custom_code
  File "/home/nachshon/Documents/Projects/WMDM/webversion/heroku/nachshon-wmdm/custom.py", line 8, in <module>
    from psiturk.experiment_errors import ExperimentError, InvalidUsageError
ImportError: cannot import name 'InvalidUsageError' from 'psiturk.experiment_errors' (/home/nachshon/anaconda3/envs/psiturk/lib/python3.8/site-packages/psiturk/experiment_errors.py)
2021-04-16 22:29:08,758 There is custom code (custom.py) associated with this                           project but it doesn't import cleanly.  Raising exception,
[2021-04-16 22:29:08 -0400] [117117] [ERROR] Exception in worker process
Traceback (most recent call last):
  File "/home/nachshon/anaconda3/envs/psiturk/lib/python3.8/site-packages/gunicorn/arbiter.py", line 583, in spawn_worker
    worker.init_process()
  File "/home/nachshon/anaconda3/envs/psiturk/lib/python3.8/site-packages/gunicorn/workers/base.py", line 129, in init_process
    self.load_wsgi()
  File "/home/nachshon/anaconda3/envs/psiturk/lib/python3.8/site-packages/gunicorn/workers/base.py", line 138, in load_wsgi
    self.wsgi = self.app.wsgi()
  File "/home/nachshon/anaconda3/envs/psiturk/lib/python3.8/site-packages/gunicorn/app/base.py", line 67, in wsgi
    self.callable = self.load()
  File "/home/nachshon/anaconda3/envs/psiturk/lib/python3.8/site-packages/psiturk/experiment_server.py", line 48, in load
    return util.import_app("psiturk.experiment:app")
  File "/home/nachshon/anaconda3/envs/psiturk/lib/python3.8/site-packages/gunicorn/util.py", line 350, in import_app
    __import__(module)
  File "/home/nachshon/anaconda3/envs/psiturk/lib/python3.8/site-packages/psiturk/experiment.py", line 77, in <module>
    from custom import custom_code
  File "/home/nachshon/Documents/Projects/WMDM/webversion/heroku/nachshon-wmdm/custom.py", line 8, in <module>
    from psiturk.experiment_errors import ExperimentError, InvalidUsageError
ImportError: cannot import name 'InvalidUsageError' from 'psiturk.experiment_errors' (/home/nachshon/anaconda3/envs/psiturk/lib/python3.8/site-packages/psiturk/experiment_errors.py)
2021-04-16 22:51:36,907 There is custom code (custom.py) associated with this                           project but it doesn't import cleanly.  Raising exception,
[2021-04-16 22:51:36 -0400] [117555] [ERROR] Exception in worker process
Traceback (most recent call last):
  File "/home/nachshon/anaconda3/envs/psiturk/lib/python3.8/site-packages/gunicorn/arbiter.py", line 583, in spawn_worker
    worker.init_process()
  File "/home/nachshon/anaconda3/envs/psiturk/lib/python3.8/site-packages/gunicorn/workers/base.py", line 129, in init_process
    self.load_wsgi()
  File "/home/nachshon/anaconda3/envs/psiturk/lib/python3.8/site-packages/gunicorn/workers/base.py", line 138, in load_wsgi
    self.wsgi = self.app.wsgi()
  File "/home/nachshon/anaconda3/envs/psiturk/lib/python3.8/site-packages/gunicorn/app/base.py", line 67, in wsgi
    self.callable = self.load()
  File "/home/nachshon/anaconda3/envs/psiturk/lib/python3.8/site-packages/psiturk/experiment_server.py", line 48, in load
    return util.import_app("psiturk.experiment:app")
  File "/home/nachshon/anaconda3/envs/psiturk/lib/python3.8/site-packages/gunicorn/util.py", line 350, in import_app
    __import__(module)
  File "/home/nachshon/anaconda3/envs/psiturk/lib/python3.8/site-packages/psiturk/experiment.py", line 77, in <module>
    from custom import custom_code
  File "/home/nachshon/Documents/Projects/WMDM/webversion/heroku/nachshon-wmdm/custom.py", line 8, in <module>
    from psiturk.experiment_errors import ExperimentError, InvalidUsageError
ImportError: cannot import name 'InvalidUsageError' from 'psiturk.experiment_errors' (/home/nachshon/anaconda3/envs/psiturk/lib/python3.8/site-packages/psiturk/experiment_errors.py)
2021-04-17 16:49:30,975 There is custom code (custom.py) associated with this                           project but it doesn't import cleanly.  Raising exception,
[2021-04-17 16:49:30 -0400] [142501] [ERROR] Exception in worker process
Traceback (most recent call last):
  File "/home/nachshon/anaconda3/envs/psiturk/lib/python3.8/site-packages/gunicorn/arbiter.py", line 583, in spawn_worker
    worker.init_process()
  File "/home/nachshon/anaconda3/envs/psiturk/lib/python3.8/site-packages/gunicorn/workers/base.py", line 129, in init_process
    self.load_wsgi()
  File "/home/nachshon/anaconda3/envs/psiturk/lib/python3.8/site-packages/gunicorn/workers/base.py", line 138, in load_wsgi
    self.wsgi = self.app.wsgi()
  File "/home/nachshon/anaconda3/envs/psiturk/lib/python3.8/site-packages/gunicorn/app/base.py", line 67, in wsgi
    self.callable = self.load()
  File "/home/nachshon/anaconda3/envs/psiturk/lib/python3.8/site-packages/psiturk/experiment_server.py", line 48, in load
    return util.import_app("psiturk.experiment:app")
  File "/home/nachshon/anaconda3/envs/psiturk/lib/python3.8/site-packages/gunicorn/util.py", line 350, in import_app
    __import__(module)
  File "/home/nachshon/anaconda3/envs/psiturk/lib/python3.8/site-packages/psiturk/experiment.py", line 77, in <module>
    from custom import custom_code
  File "/home/nachshon/Documents/Projects/WMDM/webversion/heroku/nachshon-wmdm/custom.py", line 8, in <module>
    from psiturk.experiment_errors import ExperimentError, InvalidUsageError
ImportError: cannot import name 'InvalidUsageError' from 'psiturk.experiment_errors' (/home/nachshon/anaconda3/envs/psiturk/lib/python3.8/site-packages/psiturk/experiment_errors.py)
2021-04-17 16:54:10,563 There is custom code (custom.py) associated with this                           project but it doesn't import cleanly.  Raising exception,
[2021-04-17 16:54:10 -0400] [142820] [ERROR] Exception in worker process
Traceback (most recent call last):
  File "/home/nachshon/anaconda3/envs/psiturk/lib/python3.8/site-packages/gunicorn/arbiter.py", line 583, in spawn_worker
    worker.init_process()
  File "/home/nachshon/anaconda3/envs/psiturk/lib/python3.8/site-packages/gunicorn/workers/base.py", line 129, in init_process
    self.load_wsgi()
  File "/home/nachshon/anaconda3/envs/psiturk/lib/python3.8/site-packages/gunicorn/workers/base.py", line 138, in load_wsgi
    self.wsgi = self.app.wsgi()
  File "/home/nachshon/anaconda3/envs/psiturk/lib/python3.8/site-packages/gunicorn/app/base.py", line 67, in wsgi
    self.callable = self.load()
  File "/home/nachshon/anaconda3/envs/psiturk/lib/python3.8/site-packages/psiturk/experiment_server.py", line 48, in load
    return util.import_app("psiturk.experiment:app")
  File "/home/nachshon/anaconda3/envs/psiturk/lib/python3.8/site-packages/gunicorn/util.py", line 350, in import_app
    __import__(module)
  File "/home/nachshon/anaconda3/envs/psiturk/lib/python3.8/site-packages/psiturk/experiment.py", line 77, in <module>
    from custom import custom_code
  File "/home/nachshon/Documents/Projects/WMDM/webversion/heroku/nachshon-wmdm/custom.py", line 8, in <module>
    from psiturk.experiment_errors import ExperimentError, InvalidUsageError
ImportError: cannot import name 'InvalidUsageError' from 'psiturk.experiment_errors' (/home/nachshon/anaconda3/envs/psiturk/lib/python3.8/site-packages/psiturk/experiment_errors.py)
2021-04-17 17:08:25,841 There is custom code (custom.py) associated with this                           project but it doesn't import cleanly.  Raising exception,
[2021-04-17 17:08:25 -0400] [143249] [ERROR] Exception in worker process
Traceback (most recent call last):
  File "/home/nachshon/anaconda3/envs/psiturk/lib/python3.8/site-packages/gunicorn/arbiter.py", line 583, in spawn_worker
    worker.init_process()
  File "/home/nachshon/anaconda3/envs/psiturk/lib/python3.8/site-packages/gunicorn/workers/base.py", line 129, in init_process
    self.load_wsgi()
  File "/home/nachshon/anaconda3/envs/psiturk/lib/python3.8/site-packages/gunicorn/workers/base.py", line 138, in load_wsgi
    self.wsgi = self.app.wsgi()
  File "/home/nachshon/anaconda3/envs/psiturk/lib/python3.8/site-packages/gunicorn/app/base.py", line 67, in wsgi
    self.callable = self.load()
  File "/home/nachshon/anaconda3/envs/psiturk/lib/python3.8/site-packages/psiturk/experiment_server.py", line 48, in load
    return util.import_app("psiturk.experiment:app")
  File "/home/nachshon/anaconda3/envs/psiturk/lib/python3.8/site-packages/gunicorn/util.py", line 350, in import_app
    __import__(module)
  File "/home/nachshon/anaconda3/envs/psiturk/lib/python3.8/site-packages/psiturk/experiment.py", line 77, in <module>
    from custom import custom_code
  File "/home/nachshon/Documents/Projects/WMDM/webversion/heroku/nachshon-wmdm/custom.py", line 8, in <module>
    from psiturk.experiment_errors import ExperimentError, InvalidUsageError
ImportError: cannot import name 'InvalidUsageError' from 'psiturk.experiment_errors' (/home/nachshon/anaconda3/envs/psiturk/lib/python3.8/site-packages/psiturk/experiment_errors.py)
[2021-04-27 20:37:19 -0400] [9066] [CRITICAL] WORKER TIMEOUT (pid:9069)
[2021-04-27 20:37:19 -0400] [10886] [ERROR] Exception in worker process
Traceback (most recent call last):
  File "/home/nachshon/anaconda3/envs/psiturk/lib/python3.8/site-packages/sqlalchemy/engine/base.py", line 2336, in _wrap_pool_connect
    return fn()
  File "/home/nachshon/anaconda3/envs/psiturk/lib/python3.8/site-packages/sqlalchemy/pool/base.py", line 364, in connect
    return _ConnectionFairy._checkout(self)
  File "/home/nachshon/anaconda3/envs/psiturk/lib/python3.8/site-packages/sqlalchemy/pool/base.py", line 778, in _checkout
    fairy = _ConnectionRecord.checkout(pool)
  File "/home/nachshon/anaconda3/envs/psiturk/lib/python3.8/site-packages/sqlalchemy/pool/base.py", line 495, in checkout
    rec = pool._do_get()
  File "/home/nachshon/anaconda3/envs/psiturk/lib/python3.8/site-packages/sqlalchemy/pool/impl.py", line 140, in _do_get
    self._dec_overflow()
  File "/home/nachshon/anaconda3/envs/psiturk/lib/python3.8/site-packages/sqlalchemy/util/langhelpers.py", line 68, in __exit__
    compat.raise_(
  File "/home/nachshon/anaconda3/envs/psiturk/lib/python3.8/site-packages/sqlalchemy/util/compat.py", line 182, in raise_
    raise exception
  File "/home/nachshon/anaconda3/envs/psiturk/lib/python3.8/site-packages/sqlalchemy/pool/impl.py", line 137, in _do_get
    return self._create_connection()
  File "/home/nachshon/anaconda3/envs/psiturk/lib/python3.8/site-packages/sqlalchemy/pool/base.py", line 309, in _create_connection
    return _ConnectionRecord(self)
  File "/home/nachshon/anaconda3/envs/psiturk/lib/python3.8/site-packages/sqlalchemy/pool/base.py", line 440, in __init__
    self.__connect(first_connect_check=True)
  File "/home/nachshon/anaconda3/envs/psiturk/lib/python3.8/site-packages/sqlalchemy/pool/base.py", line 661, in __connect
    pool.logger.debug("Error on connect(): %s", e)
  File "/home/nachshon/anaconda3/envs/psiturk/lib/python3.8/site-packages/sqlalchemy/util/langhelpers.py", line 68, in __exit__
    compat.raise_(
  File "/home/nachshon/anaconda3/envs/psiturk/lib/python3.8/site-packages/sqlalchemy/util/compat.py", line 182, in raise_
    raise exception
  File "/home/nachshon/anaconda3/envs/psiturk/lib/python3.8/site-packages/sqlalchemy/pool/base.py", line 656, in __connect
    connection = pool._invoke_creator(self)
  File "/home/nachshon/anaconda3/envs/psiturk/lib/python3.8/site-packages/sqlalchemy/engine/strategies.py", line 114, in connect
    return dialect.connect(*cargs, **cparams)
  File "/home/nachshon/anaconda3/envs/psiturk/lib/python3.8/site-packages/sqlalchemy/engine/default.py", line 509, in connect
    return self.dbapi.connect(*cargs, **cparams)
  File "/home/nachshon/anaconda3/envs/psiturk/lib/python3.8/site-packages/psycopg2/__init__.py", line 127, in connect
    conn = _connect(dsn, connection_factory=connection_factory, **kwasync)
psycopg2.OperationalError: could not translate host name "ec2-34-195-233-155.compute-1.amazonaws.com" to address: Temporary failure in name resolution


The above exception was the direct cause of the following exception:

Traceback (most recent call last):
  File "/home/nachshon/anaconda3/envs/psiturk/lib/python3.8/site-packages/gunicorn/arbiter.py", line 583, in spawn_worker
    worker.init_process()
  File "/home/nachshon/anaconda3/envs/psiturk/lib/python3.8/site-packages/gunicorn/workers/ggevent.py", line 162, in init_process
    super().init_process()
  File "/home/nachshon/anaconda3/envs/psiturk/lib/python3.8/site-packages/gunicorn/workers/base.py", line 119, in init_process
    self.load_wsgi()
  File "/home/nachshon/anaconda3/envs/psiturk/lib/python3.8/site-packages/gunicorn/workers/base.py", line 144, in load_wsgi
    self.wsgi = self.app.wsgi()
  File "/home/nachshon/anaconda3/envs/psiturk/lib/python3.8/site-packages/gunicorn/app/base.py", line 67, in wsgi
    self.callable = self.load()
  File "/home/nachshon/anaconda3/envs/psiturk/lib/python3.8/site-packages/psiturk/experiment_server.py", line 68, in load
    return util.import_app("psiturk.experiment:app")
  File "/home/nachshon/anaconda3/envs/psiturk/lib/python3.8/site-packages/gunicorn/util.py", line 358, in import_app
    mod = importlib.import_module(module)
  File "/home/nachshon/anaconda3/envs/psiturk/lib/python3.8/importlib/__init__.py", line 127, in import_module
    return _bootstrap._gcd_import(name[level:], package, level)
  File "<frozen importlib._bootstrap>", line 1014, in _gcd_import
  File "<frozen importlib._bootstrap>", line 991, in _find_and_load
  File "<frozen importlib._bootstrap>", line 975, in _find_and_load_unlocked
  File "<frozen importlib._bootstrap>", line 671, in _load_unlocked
  File "<frozen importlib._bootstrap_external>", line 783, in exec_module
  File "<frozen importlib._bootstrap>", line 219, in _call_with_frames_removed
  File "/home/nachshon/anaconda3/envs/psiturk/lib/python3.8/site-packages/psiturk/experiment.py", line 130, in <module>
    init_db()
  File "/home/nachshon/anaconda3/envs/psiturk/lib/python3.8/site-packages/psiturk/db.py", line 33, in init_db
    Base.metadata.create_all(bind=engine)
  File "/home/nachshon/anaconda3/envs/psiturk/lib/python3.8/site-packages/sqlalchemy/sql/schema.py", line 4553, in create_all
    bind._run_visitor(
  File "/home/nachshon/anaconda3/envs/psiturk/lib/python3.8/site-packages/sqlalchemy/engine/base.py", line 2094, in _run_visitor
    with self._optional_conn_ctx_manager(connection) as conn:
  File "/home/nachshon/anaconda3/envs/psiturk/lib/python3.8/contextlib.py", line 113, in __enter__
    return next(self.gen)
  File "/home/nachshon/anaconda3/envs/psiturk/lib/python3.8/site-packages/sqlalchemy/engine/base.py", line 2086, in _optional_conn_ctx_manager
    with self._contextual_connect() as conn:
  File "/home/nachshon/anaconda3/envs/psiturk/lib/python3.8/site-packages/sqlalchemy/engine/base.py", line 2302, in _contextual_connect
    self._wrap_pool_connect(self.pool.connect, None),
  File "/home/nachshon/anaconda3/envs/psiturk/lib/python3.8/site-packages/sqlalchemy/engine/base.py", line 2339, in _wrap_pool_connect
    Connection._handle_dbapi_exception_noconnection(
  File "/home/nachshon/anaconda3/envs/psiturk/lib/python3.8/site-packages/sqlalchemy/engine/base.py", line 1583, in _handle_dbapi_exception_noconnection
    util.raise_(
  File "/home/nachshon/anaconda3/envs/psiturk/lib/python3.8/site-packages/sqlalchemy/util/compat.py", line 182, in raise_
    raise exception
  File "/home/nachshon/anaconda3/envs/psiturk/lib/python3.8/site-packages/sqlalchemy/engine/base.py", line 2336, in _wrap_pool_connect
    return fn()
  File "/home/nachshon/anaconda3/envs/psiturk/lib/python3.8/site-packages/sqlalchemy/pool/base.py", line 364, in connect
    return _ConnectionFairy._checkout(self)
  File "/home/nachshon/anaconda3/envs/psiturk/lib/python3.8/site-packages/sqlalchemy/pool/base.py", line 778, in _checkout
    fairy = _ConnectionRecord.checkout(pool)
  File "/home/nachshon/anaconda3/envs/psiturk/lib/python3.8/site-packages/sqlalchemy/pool/base.py", line 495, in checkout
    rec = pool._do_get()
  File "/home/nachshon/anaconda3/envs/psiturk/lib/python3.8/site-packages/sqlalchemy/pool/impl.py", line 140, in _do_get
    self._dec_overflow()
  File "/home/nachshon/anaconda3/envs/psiturk/lib/python3.8/site-packages/sqlalchemy/util/langhelpers.py", line 68, in __exit__
    compat.raise_(
  File "/home/nachshon/anaconda3/envs/psiturk/lib/python3.8/site-packages/sqlalchemy/util/compat.py", line 182, in raise_
    raise exception
  File "/home/nachshon/anaconda3/envs/psiturk/lib/python3.8/site-packages/sqlalchemy/pool/impl.py", line 137, in _do_get
    return self._create_connection()
  File "/home/nachshon/anaconda3/envs/psiturk/lib/python3.8/site-packages/sqlalchemy/pool/base.py", line 309, in _create_connection
    return _ConnectionRecord(self)
  File "/home/nachshon/anaconda3/envs/psiturk/lib/python3.8/site-packages/sqlalchemy/pool/base.py", line 440, in __init__
    self.__connect(first_connect_check=True)
  File "/home/nachshon/anaconda3/envs/psiturk/lib/python3.8/site-packages/sqlalchemy/pool/base.py", line 661, in __connect
    pool.logger.debug("Error on connect(): %s", e)
  File "/home/nachshon/anaconda3/envs/psiturk/lib/python3.8/site-packages/sqlalchemy/util/langhelpers.py", line 68, in __exit__
    compat.raise_(
  File "/home/nachshon/anaconda3/envs/psiturk/lib/python3.8/site-packages/sqlalchemy/util/compat.py", line 182, in raise_
    raise exception
  File "/home/nachshon/anaconda3/envs/psiturk/lib/python3.8/site-packages/sqlalchemy/pool/base.py", line 656, in __connect
    connection = pool._invoke_creator(self)
  File "/home/nachshon/anaconda3/envs/psiturk/lib/python3.8/site-packages/sqlalchemy/engine/strategies.py", line 114, in connect
    return dialect.connect(*cargs, **cparams)
  File "/home/nachshon/anaconda3/envs/psiturk/lib/python3.8/site-packages/sqlalchemy/engine/default.py", line 509, in connect
    return self.dbapi.connect(*cargs, **cparams)
  File "/home/nachshon/anaconda3/envs/psiturk/lib/python3.8/site-packages/psycopg2/__init__.py", line 127, in connect
    conn = _connect(dsn, connection_factory=connection_factory, **kwasync)
sqlalchemy.exc.OperationalError: (psycopg2.OperationalError) could not translate host name "ec2-34-195-233-155.compute-1.amazonaws.com" to address: Temporary failure in name resolution

(Background on this error at: http://sqlalche.me/e/13/e3q8)
[2021-04-27 20:37:49 -0400] [9066] [CRITICAL] WORKER TIMEOUT (pid:10886)
[2021-04-29 22:43:55 -0400] [55057] [CRITICAL] WORKER TIMEOUT (pid:55060)
[2021-04-29 22:43:55 -0400] [69935] [ERROR] Exception in worker process
Traceback (most recent call last):
  File "/home/nachshon/anaconda3/envs/psiturk/lib/python3.8/site-packages/sqlalchemy/engine/base.py", line 2336, in _wrap_pool_connect
    return fn()
  File "/home/nachshon/anaconda3/envs/psiturk/lib/python3.8/site-packages/sqlalchemy/pool/base.py", line 364, in connect
    return _ConnectionFairy._checkout(self)
  File "/home/nachshon/anaconda3/envs/psiturk/lib/python3.8/site-packages/sqlalchemy/pool/base.py", line 778, in _checkout
    fairy = _ConnectionRecord.checkout(pool)
  File "/home/nachshon/anaconda3/envs/psiturk/lib/python3.8/site-packages/sqlalchemy/pool/base.py", line 495, in checkout
    rec = pool._do_get()
  File "/home/nachshon/anaconda3/envs/psiturk/lib/python3.8/site-packages/sqlalchemy/pool/impl.py", line 140, in _do_get
    self._dec_overflow()
  File "/home/nachshon/anaconda3/envs/psiturk/lib/python3.8/site-packages/sqlalchemy/util/langhelpers.py", line 68, in __exit__
    compat.raise_(
  File "/home/nachshon/anaconda3/envs/psiturk/lib/python3.8/site-packages/sqlalchemy/util/compat.py", line 182, in raise_
    raise exception
  File "/home/nachshon/anaconda3/envs/psiturk/lib/python3.8/site-packages/sqlalchemy/pool/impl.py", line 137, in _do_get
    return self._create_connection()
  File "/home/nachshon/anaconda3/envs/psiturk/lib/python3.8/site-packages/sqlalchemy/pool/base.py", line 309, in _create_connection
    return _ConnectionRecord(self)
  File "/home/nachshon/anaconda3/envs/psiturk/lib/python3.8/site-packages/sqlalchemy/pool/base.py", line 440, in __init__
    self.__connect(first_connect_check=True)
  File "/home/nachshon/anaconda3/envs/psiturk/lib/python3.8/site-packages/sqlalchemy/pool/base.py", line 661, in __connect
    pool.logger.debug("Error on connect(): %s", e)
  File "/home/nachshon/anaconda3/envs/psiturk/lib/python3.8/site-packages/sqlalchemy/util/langhelpers.py", line 68, in __exit__
    compat.raise_(
  File "/home/nachshon/anaconda3/envs/psiturk/lib/python3.8/site-packages/sqlalchemy/util/compat.py", line 182, in raise_
    raise exception
  File "/home/nachshon/anaconda3/envs/psiturk/lib/python3.8/site-packages/sqlalchemy/pool/base.py", line 656, in __connect
    connection = pool._invoke_creator(self)
  File "/home/nachshon/anaconda3/envs/psiturk/lib/python3.8/site-packages/sqlalchemy/engine/strategies.py", line 114, in connect
    return dialect.connect(*cargs, **cparams)
  File "/home/nachshon/anaconda3/envs/psiturk/lib/python3.8/site-packages/sqlalchemy/engine/default.py", line 509, in connect
    return self.dbapi.connect(*cargs, **cparams)
  File "/home/nachshon/anaconda3/envs/psiturk/lib/python3.8/site-packages/psycopg2/__init__.py", line 127, in connect
    conn = _connect(dsn, connection_factory=connection_factory, **kwasync)
psycopg2.OperationalError: could not translate host name "ec2-34-195-233-155.compute-1.amazonaws.com" to address: Temporary failure in name resolution


The above exception was the direct cause of the following exception:

Traceback (most recent call last):
  File "/home/nachshon/anaconda3/envs/psiturk/lib/python3.8/site-packages/gunicorn/arbiter.py", line 583, in spawn_worker
    worker.init_process()
  File "/home/nachshon/anaconda3/envs/psiturk/lib/python3.8/site-packages/gunicorn/workers/ggevent.py", line 162, in init_process
    super().init_process()
  File "/home/nachshon/anaconda3/envs/psiturk/lib/python3.8/site-packages/gunicorn/workers/base.py", line 119, in init_process
    self.load_wsgi()
  File "/home/nachshon/anaconda3/envs/psiturk/lib/python3.8/site-packages/gunicorn/workers/base.py", line 144, in load_wsgi
    self.wsgi = self.app.wsgi()
  File "/home/nachshon/anaconda3/envs/psiturk/lib/python3.8/site-packages/gunicorn/app/base.py", line 67, in wsgi
    self.callable = self.load()
  File "/home/nachshon/anaconda3/envs/psiturk/lib/python3.8/site-packages/psiturk/experiment_server.py", line 68, in load
    return util.import_app("psiturk.experiment:app")
  File "/home/nachshon/anaconda3/envs/psiturk/lib/python3.8/site-packages/gunicorn/util.py", line 358, in import_app
    mod = importlib.import_module(module)
  File "/home/nachshon/anaconda3/envs/psiturk/lib/python3.8/importlib/__init__.py", line 127, in import_module
    return _bootstrap._gcd_import(name[level:], package, level)
  File "<frozen importlib._bootstrap>", line 1014, in _gcd_import
  File "<frozen importlib._bootstrap>", line 991, in _find_and_load
  File "<frozen importlib._bootstrap>", line 975, in _find_and_load_unlocked
  File "<frozen importlib._bootstrap>", line 671, in _load_unlocked
  File "<frozen importlib._bootstrap_external>", line 783, in exec_module
  File "<frozen importlib._bootstrap>", line 219, in _call_with_frames_removed
  File "/home/nachshon/anaconda3/envs/psiturk/lib/python3.8/site-packages/psiturk/experiment.py", line 130, in <module>
    init_db()
  File "/home/nachshon/anaconda3/envs/psiturk/lib/python3.8/site-packages/psiturk/db.py", line 33, in init_db
    Base.metadata.create_all(bind=engine)
  File "/home/nachshon/anaconda3/envs/psiturk/lib/python3.8/site-packages/sqlalchemy/sql/schema.py", line 4553, in create_all
    bind._run_visitor(
  File "/home/nachshon/anaconda3/envs/psiturk/lib/python3.8/site-packages/sqlalchemy/engine/base.py", line 2094, in _run_visitor
    with self._optional_conn_ctx_manager(connection) as conn:
  File "/home/nachshon/anaconda3/envs/psiturk/lib/python3.8/contextlib.py", line 113, in __enter__
    return next(self.gen)
  File "/home/nachshon/anaconda3/envs/psiturk/lib/python3.8/site-packages/sqlalchemy/engine/base.py", line 2086, in _optional_conn_ctx_manager
    with self._contextual_connect() as conn:
  File "/home/nachshon/anaconda3/envs/psiturk/lib/python3.8/site-packages/sqlalchemy/engine/base.py", line 2302, in _contextual_connect
    self._wrap_pool_connect(self.pool.connect, None),
  File "/home/nachshon/anaconda3/envs/psiturk/lib/python3.8/site-packages/sqlalchemy/engine/base.py", line 2339, in _wrap_pool_connect
    Connection._handle_dbapi_exception_noconnection(
  File "/home/nachshon/anaconda3/envs/psiturk/lib/python3.8/site-packages/sqlalchemy/engine/base.py", line 1583, in _handle_dbapi_exception_noconnection
    util.raise_(
  File "/home/nachshon/anaconda3/envs/psiturk/lib/python3.8/site-packages/sqlalchemy/util/compat.py", line 182, in raise_
    raise exception
  File "/home/nachshon/anaconda3/envs/psiturk/lib/python3.8/site-packages/sqlalchemy/engine/base.py", line 2336, in _wrap_pool_connect
    return fn()
  File "/home/nachshon/anaconda3/envs/psiturk/lib/python3.8/site-packages/sqlalchemy/pool/base.py", line 364, in connect
    return _ConnectionFairy._checkout(self)
  File "/home/nachshon/anaconda3/envs/psiturk/lib/python3.8/site-packages/sqlalchemy/pool/base.py", line 778, in _checkout
    fairy = _ConnectionRecord.checkout(pool)
  File "/home/nachshon/anaconda3/envs/psiturk/lib/python3.8/site-packages/sqlalchemy/pool/base.py", line 495, in checkout
    rec = pool._do_get()
  File "/home/nachshon/anaconda3/envs/psiturk/lib/python3.8/site-packages/sqlalchemy/pool/impl.py", line 140, in _do_get
    self._dec_overflow()
  File "/home/nachshon/anaconda3/envs/psiturk/lib/python3.8/site-packages/sqlalchemy/util/langhelpers.py", line 68, in __exit__
    compat.raise_(
  File "/home/nachshon/anaconda3/envs/psiturk/lib/python3.8/site-packages/sqlalchemy/util/compat.py", line 182, in raise_
    raise exception
  File "/home/nachshon/anaconda3/envs/psiturk/lib/python3.8/site-packages/sqlalchemy/pool/impl.py", line 137, in _do_get
    return self._create_connection()
  File "/home/nachshon/anaconda3/envs/psiturk/lib/python3.8/site-packages/sqlalchemy/pool/base.py", line 309, in _create_connection
    return _ConnectionRecord(self)
  File "/home/nachshon/anaconda3/envs/psiturk/lib/python3.8/site-packages/sqlalchemy/pool/base.py", line 440, in __init__
    self.__connect(first_connect_check=True)
  File "/home/nachshon/anaconda3/envs/psiturk/lib/python3.8/site-packages/sqlalchemy/pool/base.py", line 661, in __connect
    pool.logger.debug("Error on connect(): %s", e)
  File "/home/nachshon/anaconda3/envs/psiturk/lib/python3.8/site-packages/sqlalchemy/util/langhelpers.py", line 68, in __exit__
    compat.raise_(
  File "/home/nachshon/anaconda3/envs/psiturk/lib/python3.8/site-packages/sqlalchemy/util/compat.py", line 182, in raise_
    raise exception
  File "/home/nachshon/anaconda3/envs/psiturk/lib/python3.8/site-packages/sqlalchemy/pool/base.py", line 656, in __connect
    connection = pool._invoke_creator(self)
  File "/home/nachshon/anaconda3/envs/psiturk/lib/python3.8/site-packages/sqlalchemy/engine/strategies.py", line 114, in connect
    return dialect.connect(*cargs, **cparams)
  File "/home/nachshon/anaconda3/envs/psiturk/lib/python3.8/site-packages/sqlalchemy/engine/default.py", line 509, in connect
    return self.dbapi.connect(*cargs, **cparams)
  File "/home/nachshon/anaconda3/envs/psiturk/lib/python3.8/site-packages/psycopg2/__init__.py", line 127, in connect
    conn = _connect(dsn, connection_factory=connection_factory, **kwasync)
sqlalchemy.exc.OperationalError: (psycopg2.OperationalError) could not translate host name "ec2-34-195-233-155.compute-1.amazonaws.com" to address: Temporary failure in name resolution

(Background on this error at: http://sqlalche.me/e/13/e3q8)
[2021-04-29 22:44:25 -0400] [55057] [CRITICAL] WORKER TIMEOUT (pid:69935)
